Workbook
Name CollisionThreshold: Settings!$B$6
Name FilterList: OFFSET(Lists!$K$5,0,0,MAX(1,COUNTIF(Lists!$K$5:$K$16,"?*")),1)
Name MonthList: Lists!$M$5:$M$16
Name MotionNames: Lists!$E$5:$E$7
Name PlanYear: Settings!$B$4
Name PracticeList: OFFSET(Lists!$B$5,0,0,MAX(1,COUNTA(Lists!$B$5:$B$16)),1)
Name PracticeNames: Lists!$B$5:$B$16
Name SelMonthNum: 'Monthly View'!$K$1
Name SelPractice: 'Practice View'!$B$5
Name StatusFilter: Settings!$B$5
Name StatusList: OFFSET(Lists!$I$5,0,0,MAX(1,COUNTA(Lists!$I$5:$I$14)),1)
Name TypeList: OFFSET(Lists!$G$5,0,0,MAX(1,COUNTA(Lists!$G$5:$G$24)),1)

Sheet Start Here
B1: THE INTEGRATED VIEW
B2: Integrated Marketing Calendar
B3: One place to plan the whole motion - connect it, compound it, coordinate it.
B5: HOW IT WORKS
B6: 1. Enter activities | C6: Go to Activity Planner. One row per activity: name, practice, motion, type, start (and end) date, status. Everything else updates itself.
B7: 2. Read the views | C7: Annual View = the whole year by practice and month. Monthly View = pick a month. Practice View = pick a practice.
B8: 3. Add a practice | C8: Lists sheet > Practices: type the new name in the next yellow cell. It appears in the dropdowns and all views (room for 12).
B9: 4. Roll the year | C9: Settings > Planning year. Update dates in the planner; clear sample rows first.
B11: THE THREE MOTIONS
B12: Create the reason to care | C12: Why should the market care? Point of view, research, market insight.
B13: Build momentum | C13: Keep the story moving. PR, campaigns, launches, events, executive visibility.
B14: Create opportunity | C14: Turn attention into conversations. Client activation, webinars, roundtables, outreach, follow-up.
B16: THE THREE PRINCIPLES
B17: CONNECT | C17: See where one market moment or activity can support multiple priorities.
B18: COMPOUND | C18: Build on existing momentum rather than creating isolated activity from scratch.
B19: COORDINATE | C19: Identify collisions, gaps and opportunities for better sequencing across the portfolio.
B21: GOOD TO KNOW
B22: Multi-month activities | C22: An activity from 1-Mar to 15-May counts in March, April and May. Year totals count it once.
B23: Status filter | C23: Settings > Status filter. Default hides Cancelled. Applies to every view.
B24: Red row in planner | C24: The Check column explains what is missing (practice, motion, date...).
B25: Several editors | C25: Keep the file on SharePoint/OneDrive so people can edit together. Only edit Activity Planner, Lists and Settings. View sheets are locked (no password).
B26: Sample data | C26: The 19 sample rows are from the original slide. Delete or overwrite them. Do not delete rows - clear their contents.
B27: Capacity | C27: 1000 activity rows, 12 practices, 20 activity types.

Sheet Annual View
A1: THE INTEGRATED VIEW
A2: See the whole motion. Build on what's already happening.
A3: Launches, thought leadership, PR, campaigns, events and client activation in one view, so activity can connect, compound and create sustained opportunity.
A4: ="Planning year "&PlanYear&" | Showing: "&StatusFilter&" (change on the Settings sheet)" -> 0
A6: PRIORITY | B6: JAN | C6: FEB | D6: MAR | E6: APR | F6: MAY | G6: JUN | H6: JUL | I6: AUG | J6: SEP | K6: OCT | L6: NOV | M6: DEC
A7: =IF(Lists!$B$5="","",Lists!$B$5) -> 0 | B7: {=IF($A7="","",_xlfn.TEXTJOIN(CHAR(10),TRUE,IFERROR(INDEX('Activity Planner'!$B$5:$B$1004,SMALL(IF(('Activity Planner'!$C$5:$C$1004=$A7)*('Activity Planner'!$O$5:$O$1004=1),ROW('Activity Planner'!$B$5:$B$1004)-4),{1,2,3})),""))&IF(Calc!B3>3,CHAR(10)&"+"&(Calc!B3-3)&" more",""))} -> 0 | C7: {=IF($A7="","",_xlfn.TEXTJOIN(CHAR(10),TRUE,IFERROR(INDEX('Activity Planner'!$B$5:$B$1004,SMALL(IF(('Activity Planner'!$C$5:$C$1004=$A7)*('Activity Planner'!$P$5:$P$1004=1),ROW('Activity Planner'!$B$5:$B$1004)-4),{1,2,3})),""))&IF(Calc!C3>3,CHAR(10)&"+"&(Calc!C3-3)&" more",""))} -> 0 | D7: {=IF($A7="","",_xlfn.TEXTJOIN(CHAR(10),TRUE,IFERROR(INDEX('Activity Planner'!$B$5:$B$1004,SMALL(IF(('Activity Planner'!$C$5:$C$1004=$A7)*('Activity Planner'!$Q$5:$Q$1004=1),ROW('Activity Planner'!$B$5:$B$1004)-4),{1,2,3})),""))&IF(Calc!D3>3,CHAR(10)&"+"&(Calc!D3-3)&" more",""))} -> 0 | E7: {=IF($A7="","",_xlfn.TEXTJOIN(CHAR(10),TRUE,IFERROR(INDEX('Activity Planner'!$B$5:$B$1004,SMALL(IF(('Activity Planner'!$C$5:$C$1004=$A7)*('Activity Planner'!$R$5:$R$1004=1),ROW('Activity Planner'!$B$5:$B$1004)-4),{1,2,3})),""))&IF(Calc!E3>3,CHAR(10)&"+"&(Calc!E3-3)&" more",""))} -> 0 | F7: {=IF($A7="","",_xlfn.TEXTJOIN(CHAR(10),TRUE,IFERROR(INDEX('Activity Planner'!$B$5:$B$1004,SMALL(IF(('Activity Planner'!$C$5:$C$1004=$A7)*('Activity Planner'!$S$5:$S$1004=1),ROW('Activity Planner'!$B$5:$B$1004)-4),{1,2,3})),""))&IF(Calc!F3>3,CHAR(10)&"+"&(Calc!F3-3)&" more",""))} -> 0 | G7: {=IF($A7="","",_xlfn.TEXTJOIN(CHAR(10),TRUE,IFERROR(INDEX('Activity Planner'!$B$5:$B$1004,SMALL(IF(('Activity Planner'!$C$5:$C$1004=$A7)*('Activity Planner'!$T$5:$T$1004=1),ROW('Activity Planner'!$B$5:$B$1004)-4),{1,2,3})),""))&IF(Calc!G3>3,CHAR(10)&"+"&(Calc!G3-3)&" more",""))} -> 0 | H7: {=IF($A7="","",_xlfn.TEXTJOIN(CHAR(10),TRUE,IFERROR(INDEX('Activity Planner'!$B$5:$B$1004,SMALL(IF(('Activity Planner'!$C$5:$C$1004=$A7)*('Activity Planner'!$U$5:$U$1004=1),ROW('Activity Planner'!$B$5:$B$1004)-4),{1,2,3})),""))&IF(Calc!H3>3,CHAR(10)&"+"&(Calc!H3-3)&" more",""))} -> 0 | I7: {=IF($A7="","",_xlfn.TEXTJOIN(CHAR(10),TRUE,IFERROR(INDEX('Activity Planner'!$B$5:$B$1004,SMALL(IF(('Activity Planner'!$C$5:$C$1004=$A7)*('Activity Planner'!$V$5:$V$1004=1),ROW('Activity Planner'!$B$5:$B$1004)-4),{1,2,3})),""))&IF(Calc!I3>3,CHAR(10)&"+"&(Calc!I3-3)&" more",""))} -> 0 | J7: {=IF($A7="","",_xlfn.TEXTJOIN(CHAR(10),TRUE,IFERROR(INDEX('Activity Planner'!$B$5:$B$1004,SMALL(IF(('Activity Planner'!$C$5:$C$1004=$A7)*('Activity Planner'!$W$5:$W$1004=1),ROW('Activity Planner'!$B$5:$B$1004)-4),{1,2,3})),""))&IF(Calc!J3>3,CHAR(10)&"+"&(Calc!J3-3)&" more",""))} -> 0 | K7: {=IF($A7="","",_xlfn.TEXTJOIN(CHAR(10),TRUE,IFERROR(INDEX('Activity Planner'!$B$5:$B$1004,SMALL(IF(('Activity Planner'!$C$5:$C$1004=$A7)*('Activity Planner'!$X$5:$X$1004=1),ROW('Activity Planner'!$B$5:$B$1004)-4),{1,2,3})),""))&IF(Calc!K3>3,CHAR(10)&"+"&(Calc!K3-3)&" more",""))} -> 0 | L7: {=IF($A7="","",_xlfn.TEXTJOIN(CHAR(10),TRUE,IFERROR(INDEX('Activity Planner'!$B$5:$B$1004,SMALL(IF(('Activity Planner'!$C$5:$C$1004=$A7)*('Activity Planner'!$Y$5:$Y$1004=1),ROW('Activity Planner'!$B$5:$B$1004)-4),{1,2,3})),""))&IF(Calc!L3>3,CHAR(10)&"+"&(Calc!L3-3)&" more",""))} -> 0 | M7: {=IF($A7="","",_xlfn.TEXTJOIN(CHAR(10),TRUE,IFERROR(INDEX('Activity Planner'!$B$5:$B$1004,SMALL(IF(('Activity Planner'!$C$5:$C$1004=$A7)*('Activity Planner'!$Z$5:$Z$1004=1),ROW('Activity Planner'!$B$5:$B$1004)-4),{1,2,3})),""))&IF(Calc!M3>3,CHAR(10)&"+"&(Calc!M3-3)&" more",""))} -> 0
A8: =IF(Lists!$B$6="","",Lists!$B$6) -> 0 | B8: {=IF($A8="","",_xlfn.TEXTJOIN(CHAR(10),TRUE,IFERROR(INDEX('Activity Planner'!$B$5:$B$1004,SMALL(IF(('Activity Planner'!$C$5:$C$1004=$A8)*('Activity Planner'!$O$5:$O$1004=1),ROW('Activity Planner'!$B$5:$B$1004)-4),{1,2,3})),""))&IF(Calc!B4>3,CHAR(10)&"+"&(Calc!B4-3)&" more",""))} -> 0 | C8: {=IF($A8="","",_xlfn.TEXTJOIN(CHAR(10),TRUE,IFERROR(INDEX('Activity Planner'!$B$5:$B$1004,SMALL(IF(('Activity Planner'!$C$5:$C$1004=$A8)*('Activity Planner'!$P$5:$P$1004=1),ROW('Activity Planner'!$B$5:$B$1004)-4),{1,2,3})),""))&IF(Calc!C4>3,CHAR(10)&"+"&(Calc!C4-3)&" more",""))} -> 0 | D8: {=IF($A8="","",_xlfn.TEXTJOIN(CHAR(10),TRUE,IFERROR(INDEX('Activity Planner'!$B$5:$B$1004,SMALL(IF(('Activity Planner'!$C$5:$C$1004=$A8)*('Activity Planner'!$Q$5:$Q$1004=1),ROW('Activity Planner'!$B$5:$B$1004)-4),{1,2,3})),""))&IF(Calc!D4>3,CHAR(10)&"+"&(Calc!D4-3)&" more",""))} -> 0 | E8: {=IF($A8="","",_xlfn.TEXTJOIN(CHAR(10),TRUE,IFERROR(INDEX('Activity Planner'!$B$5:$B$1004,SMALL(IF(('Activity Planner'!$C$5:$C$1004=$A8)*('Activity Planner'!$R$5:$R$1004=1),ROW('Activity Planner'!$B$5:$B$1004)-4),{1,2,3})),""))&IF(Calc!E4>3,CHAR(10)&"+"&(Calc!E4-3)&" more",""))} -> 0 | F8: {=IF($A8="","",_xlfn.TEXTJOIN(CHAR(10),TRUE,IFERROR(INDEX('Activity Planner'!$B$5:$B$1004,SMALL(IF(('Activity Planner'!$C$5:$C$1004=$A8)*('Activity Planner'!$S$5:$S$1004=1),ROW('Activity Planner'!$B$5:$B$1004)-4),{1,2,3})),""))&IF(Calc!F4>3,CHAR(10)&"+"&(Calc!F4-3)&" more",""))} -> 0 | G8: {=IF($A8="","",_xlfn.TEXTJOIN(CHAR(10),TRUE,IFERROR(INDEX('Activity Planner'!$B$5:$B$1004,SMALL(IF(('Activity Planner'!$C$5:$C$1004=$A8)*('Activity Planner'!$T$5:$T$1004=1),ROW('Activity Planner'!$B$5:$B$1004)-4),{1,2,3})),""))&IF(Calc!G4>3,CHAR(10)&"+"&(Calc!G4-3)&" more",""))} -> 0 | H8: {=IF($A8="","",_xlfn.TEXTJOIN(CHAR(10),TRUE,IFERROR(INDEX('Activity Planner'!$B$5:$B$1004,SMALL(IF(('Activity Planner'!$C$5:$C$1004=$A8)*('Activity Planner'!$U$5:$U$1004=1),ROW('Activity Planner'!$B$5:$B$1004)-4),{1,2,3})),""))&IF(Calc!H4>3,CHAR(10)&"+"&(Calc!H4-3)&" more",""))} -> 0 | I8: {=IF($A8="","",_xlfn.TEXTJOIN(CHAR(10),TRUE,IFERROR(INDEX('Activity Planner'!$B$5:$B$1004,SMALL(IF(('Activity Planner'!$C$5:$C$1004=$A8)*('Activity Planner'!$V$5:$V$1004=1),ROW('Activity Planner'!$B$5:$B$1004)-4),{1,2,3})),""))&IF(Calc!I4>3,CHAR(10)&"+"&(Calc!I4-3)&" more",""))} -> 0 | J8: {=IF($A8="","",_xlfn.TEXTJOIN(CHAR(10),TRUE,IFERROR(INDEX('Activity Planner'!$B$5:$B$1004,SMALL(IF(('Activity Planner'!$C$5:$C$1004=$A8)*('Activity Planner'!$W$5:$W$1004=1),ROW('Activity Planner'!$B$5:$B$1004)-4),{1,2,3})),""))&IF(Calc!J4>3,CHAR(10)&"+"&(Calc!J4-3)&" more",""))} -> 0 | K8: {=IF($A8="","",_xlfn.TEXTJOIN(CHAR(10),TRUE,IFERROR(INDEX('Activity Planner'!$B$5:$B$1004,SMALL(IF(('Activity Planner'!$C$5:$C$1004=$A8)*('Activity Planner'!$X$5:$X$1004=1),ROW('Activity Planner'!$B$5:$B$1004)-4),{1,2,3})),""))&IF(Calc!K4>3,CHAR(10)&"+"&(Calc!K4-3)&" more",""))} -> 0 | L8: {=IF($A8="","",_xlfn.TEXTJOIN(CHAR(10),TRUE,IFERROR(INDEX('Activity Planner'!$B$5:$B$1004,SMALL(IF(('Activity Planner'!$C$5:$C$1004=$A8)*('Activity Planner'!$Y$5:$Y$1004=1),ROW('Activity Planner'!$B$5:$B$1004)-4),{1,2,3})),""))&IF(Calc!L4>3,CHAR(10)&"+"&(Calc!L4-3)&" more",""))} -> 0 | M8: {=IF($A8="","",_xlfn.TEXTJOIN(CHAR(10),TRUE,IFERROR(INDEX('Activity Planner'!$B$5:$B$1004,SMALL(IF(('Activity Planner'!$C$5:$C$1004=$A8)*('Activity Planner'!$Z$5:$Z$1004=1),ROW('Activity Planner'!$B$5:$B$1004)-4),{1,2,3})),""))&IF(Calc!M4>3,CHAR(10)&"+"&(Calc!M4-3)&" more",""))} -> 0
A9: =IF(Lists!$B$7="","",Lists!$B$7) -> 0 | B9: {=IF($A9="","",_xlfn.TEXTJOIN(CHAR(10),TRUE,IFERROR(INDEX('Activity Planner'!$B$5:$B$1004,SMALL(IF(('Activity Planner'!$C$5:$C$1004=$A9)*('Activity Planner'!$O$5:$O$1004=1),ROW('Activity Planner'!$B$5:$B$1004)-4),{1,2,3})),""))&IF(Calc!B5>3,CHAR(10)&"+"&(Calc!B5-3)&" more",""))} -> 0 | C9: {=IF($A9="","",_xlfn.TEXTJOIN(CHAR(10),TRUE,IFERROR(INDEX('Activity Planner'!$B$5:$B$1004,SMALL(IF(('Activity Planner'!$C$5:$C$1004=$A9)*('Activity Planner'!$P$5:$P$1004=1),ROW('Activity Planner'!$B$5:$B$1004)-4),{1,2,3})),""))&IF(Calc!C5>3,CHAR(10)&"+"&(Calc!C5-3)&" more",""))} -> 0 | D9: {=IF($A9="","",_xlfn.TEXTJOIN(CHAR(10),TRUE,IFERROR(INDEX('Activity Planner'!$B$5:$B$1004,SMALL(IF(('Activity Planner'!$C$5:$C$1004=$A9)*('Activity Planner'!$Q$5:$Q$1004=1),ROW('Activity Planner'!$B$5:$B$1004)-4),{1,2,3})),""))&IF(Calc!D5>3,CHAR(10)&"+"&(Calc!D5-3)&" more",""))} -> 0 | E9: {=IF($A9="","",_xlfn.TEXTJOIN(CHAR(10),TRUE,IFERROR(INDEX('Activity Planner'!$B$5:$B$1004,SMALL(IF(('Activity Planner'!$C$5:$C$1004=$A9)*('Activity Planner'!$R$5:$R$1004=1),ROW('Activity Planner'!$B$5:$B$1004)-4),{1,2,3})),""))&IF(Calc!E5>3,CHAR(10)&"+"&(Calc!E5-3)&" more",""))} -> 0 | F9: {=IF($A9="","",_xlfn.TEXTJOIN(CHAR(10),TRUE,IFERROR(INDEX('Activity Planner'!$B$5:$B$1004,SMALL(IF(('Activity Planner'!$C$5:$C$1004=$A9)*('Activity Planner'!$S$5:$S$1004=1),ROW('Activity Planner'!$B$5:$B$1004)-4),{1,2,3})),""))&IF(Calc!F5>3,CHAR(10)&"+"&(Calc!F5-3)&" more",""))} -> 0 | G9: {=IF($A9="","",_xlfn.TEXTJOIN(CHAR(10),TRUE,IFERROR(INDEX('Activity Planner'!$B$5:$B$1004,SMALL(IF(('Activity Planner'!$C$5:$C$1004=$A9)*('Activity Planner'!$T$5:$T$1004=1),ROW('Activity Planner'!$B$5:$B$1004)-4),{1,2,3})),""))&IF(Calc!G5>3,CHAR(10)&"+"&(Calc!G5-3)&" more",""))} -> 0 | H9: {=IF($A9="","",_xlfn.TEXTJOIN(CHAR(10),TRUE,IFERROR(INDEX('Activity Planner'!$B$5:$B$1004,SMALL(IF(('Activity Planner'!$C$5:$C$1004=$A9)*('Activity Planner'!$U$5:$U$1004=1),ROW('Activity Planner'!$B$5:$B$1004)-4),{1,2,3})),""))&IF(Calc!H5>3,CHAR(10)&"+"&(Calc!H5-3)&" more",""))} -> 0 | I9: {=IF($A9="","",_xlfn.TEXTJOIN(CHAR(10),TRUE,IFERROR(INDEX('Activity Planner'!$B$5:$B$1004,SMALL(IF(('Activity Planner'!$C$5:$C$1004=$A9)*('Activity Planner'!$V$5:$V$1004=1),ROW('Activity Planner'!$B$5:$B$1004)-4),{1,2,3})),""))&IF(Calc!I5>3,CHAR(10)&"+"&(Calc!I5-3)&" more",""))} -> 0 | J9: {=IF($A9="","",_xlfn.TEXTJOIN(CHAR(10),TRUE,IFERROR(INDEX('Activity Planner'!$B$5:$B$1004,SMALL(IF(('Activity Planner'!$C$5:$C$1004=$A9)*('Activity Planner'!$W$5:$W$1004=1),ROW('Activity Planner'!$B$5:$B$1004)-4),{1,2,3})),""))&IF(Calc!J5>3,CHAR(10)&"+"&(Calc!J5-3)&" more",""))} -> 0 | K9: {=IF($A9="","",_xlfn.TEXTJOIN(CHAR(10),TRUE,IFERROR(INDEX('Activity Planner'!$B$5:$B$1004,SMALL(IF(('Activity Planner'!$C$5:$C$1004=$A9)*('Activity Planner'!$X$5:$X$1004=1),ROW('Activity Planner'!$B$5:$B$1004)-4),{1,2,3})),""))&IF(Calc!K5>3,CHAR(10)&"+"&(Calc!K5-3)&" more",""))} -> 0 | L9: {=IF($A9="","",_xlfn.TEXTJOIN(CHAR(10),TRUE,IFERROR(INDEX('Activity Planner'!$B$5:$B$1004,SMALL(IF(('Activity Planner'!$C$5:$C$1004=$A9)*('Activity Planner'!$Y$5:$Y$1004=1),ROW('Activity Planner'!$B$5:$B$1004)-4),{1,2,3})),""))&IF(Calc!L5>3,CHAR(10)&"+"&(Calc!L5-3)&" more",""))} -> 0 | M9: {=IF($A9="","",_xlfn.TEXTJOIN(CHAR(10),TRUE,IFERROR(INDEX('Activity Planner'!$B$5:$B$1004,SMALL(IF(('Activity Planner'!$C$5:$C$1004=$A9)*('Activity Planner'!$Z$5:$Z$1004=1),ROW('Activity Planner'!$B$5:$B$1004)-4),{1,2,3})),""))&IF(Calc!M5>3,CHAR(10)&"+"&(Calc!M5-3)&" more",""))} -> 0
A10: =IF(Lists!$B$8="","",Lists!$B$8) -> 0 | B10: {=IF($A10="","",_xlfn.TEXTJOIN(CHAR(10),TRUE,IFERROR(INDEX('Activity Planner'!$B$5:$B$1004,SMALL(IF(('Activity Planner'!$C$5:$C$1004=$A10)*('Activity Planner'!$O$5:$O$1004=1),ROW('Activity Planner'!$B$5:$B$1004)-4),{1,2,3})),""))&IF(Calc!B6>3,CHAR(10)&"+"&(Calc!B6-3)&" more",""))} -> 0 | C10: {=IF($A10="","",_xlfn.TEXTJOIN(CHAR(10),TRUE,IFERROR(INDEX('Activity Planner'!$B$5:$B$1004,SMALL(IF(('Activity Planner'!$C$5:$C$1004=$A10)*('Activity Planner'!$P$5:$P$1004=1),ROW('Activity Planner'!$B$5:$B$1004)-4),{1,2,3})),""))&IF(Calc!C6>3,CHAR(10)&"+"&(Calc!C6-3)&" more",""))} -> 0 | D10: {=IF($A10="","",_xlfn.TEXTJOIN(CHAR(10),TRUE,IFERROR(INDEX('Activity Planner'!$B$5:$B$1004,SMALL(IF(('Activity Planner'!$C$5:$C$1004=$A10)*('Activity Planner'!$Q$5:$Q$1004=1),ROW('Activity Planner'!$B$5:$B$1004)-4),{1,2,3})),""))&IF(Calc!D6>3,CHAR(10)&"+"&(Calc!D6-3)&" more",""))} -> 0 | E10: {=IF($A10="","",_xlfn.TEXTJOIN(CHAR(10),TRUE,IFERROR(INDEX('Activity Planner'!$B$5:$B$1004,SMALL(IF(('Activity Planner'!$C$5:$C$1004=$A10)*('Activity Planner'!$R$5:$R$1004=1),ROW('Activity Planner'!$B$5:$B$1004)-4),{1,2,3})),""))&IF(Calc!E6>3,CHAR(10)&"+"&(Calc!E6-3)&" more",""))} -> 0 | F10: {=IF($A10="","",_xlfn.TEXTJOIN(CHAR(10),TRUE,IFERROR(INDEX('Activity Planner'!$B$5:$B$1004,SMALL(IF(('Activity Planner'!$C$5:$C$1004=$A10)*('Activity Planner'!$S$5:$S$1004=1),ROW('Activity Planner'!$B$5:$B$1004)-4),{1,2,3})),""))&IF(Calc!F6>3,CHAR(10)&"+"&(Calc!F6-3)&" more",""))} -> 0 | G10: {=IF($A10="","",_xlfn.TEXTJOIN(CHAR(10),TRUE,IFERROR(INDEX('Activity Planner'!$B$5:$B$1004,SMALL(IF(('Activity Planner'!$C$5:$C$1004=$A10)*('Activity Planner'!$T$5:$T$1004=1),ROW('Activity Planner'!$B$5:$B$1004)-4),{1,2,3})),""))&IF(Calc!G6>3,CHAR(10)&"+"&(Calc!G6-3)&" more",""))} -> 0 | H10: {=IF($A10="","",_xlfn.TEXTJOIN(CHAR(10),TRUE,IFERROR(INDEX('Activity Planner'!$B$5:$B$1004,SMALL(IF(('Activity Planner'!$C$5:$C$1004=$A10)*('Activity Planner'!$U$5:$U$1004=1),ROW('Activity Planner'!$B$5:$B$1004)-4),{1,2,3})),""))&IF(Calc!H6>3,CHAR(10)&"+"&(Calc!H6-3)&" more",""))} -> 0 | I10: {=IF($A10="","",_xlfn.TEXTJOIN(CHAR(10),TRUE,IFERROR(INDEX('Activity Planner'!$B$5:$B$1004,SMALL(IF(('Activity Planner'!$C$5:$C$1004=$A10)*('Activity Planner'!$V$5:$V$1004=1),ROW('Activity Planner'!$B$5:$B$1004)-4),{1,2,3})),""))&IF(Calc!I6>3,CHAR(10)&"+"&(Calc!I6-3)&" more",""))} -> 0 | J10: {=IF($A10="","",_xlfn.TEXTJOIN(CHAR(10),TRUE,IFERROR(INDEX('Activity Planner'!$B$5:$B$1004,SMALL(IF(('Activity Planner'!$C$5:$C$1004=$A10)*('Activity Planner'!$W$5:$W$1004=1),ROW('Activity Planner'!$B$5:$B$1004)-4),{1,2,3})),""))&IF(Calc!J6>3,CHAR(10)&"+"&(Calc!J6-3)&" more",""))} -> 0 | K10: {=IF($A10="","",_xlfn.TEXTJOIN(CHAR(10),TRUE,IFERROR(INDEX('Activity Planner'!$B$5:$B$1004,SMALL(IF(('Activity Planner'!$C$5:$C$1004=$A10)*('Activity Planner'!$X$5:$X$1004=1),ROW('Activity Planner'!$B$5:$B$1004)-4),{1,2,3})),""))&IF(Calc!K6>3,CHAR(10)&"+"&(Calc!K6-3)&" more",""))} -> 0 | L10: {=IF($A10="","",_xlfn.TEXTJOIN(CHAR(10),TRUE,IFERROR(INDEX('Activity Planner'!$B$5:$B$1004,SMALL(IF(('Activity Planner'!$C$5:$C$1004=$A10)*('Activity Planner'!$Y$5:$Y$1004=1),ROW('Activity Planner'!$B$5:$B$1004)-4),{1,2,3})),""))&IF(Calc!L6>3,CHAR(10)&"+"&(Calc!L6-3)&" more",""))} -> 0 | M10: {=IF($A10="","",_xlfn.TEXTJOIN(CHAR(10),TRUE,IFERROR(INDEX('Activity Planner'!$B$5:$B$1004,SMALL(IF(('Activity Planner'!$C$5:$C$1004=$A10)*('Activity Planner'!$Z$5:$Z$1004=1),ROW('Activity Planner'!$B$5:$B$1004)-4),{1,2,3})),""))&IF(Calc!M6>3,CHAR(10)&"+"&(Calc!M6-3)&" more",""))} -> 0
A11: =IF(Lists!$B$9="","",Lists!$B$9) -> 0 | B11: {=IF($A11="","",_xlfn.TEXTJOIN(CHAR(10),TRUE,IFERROR(INDEX('Activity Planner'!$B$5:$B$1004,SMALL(IF(('Activity Planner'!$C$5:$C$1004=$A11)*('Activity Planner'!$O$5:$O$1004=1),ROW('Activity Planner'!$B$5:$B$1004)-4),{1,2,3})),""))&IF(Calc!B7>3,CHAR(10)&"+"&(Calc!B7-3)&" more",""))} -> 0 | C11: {=IF($A11="","",_xlfn.TEXTJOIN(CHAR(10),TRUE,IFERROR(INDEX('Activity Planner'!$B$5:$B$1004,SMALL(IF(('Activity Planner'!$C$5:$C$1004=$A11)*('Activity Planner'!$P$5:$P$1004=1),ROW('Activity Planner'!$B$5:$B$1004)-4),{1,2,3})),""))&IF(Calc!C7>3,CHAR(10)&"+"&(Calc!C7-3)&" more",""))} -> 0 | D11: {=IF($A11="","",_xlfn.TEXTJOIN(CHAR(10),TRUE,IFERROR(INDEX('Activity Planner'!$B$5:$B$1004,SMALL(IF(('Activity Planner'!$C$5:$C$1004=$A11)*('Activity Planner'!$Q$5:$Q$1004=1),ROW('Activity Planner'!$B$5:$B$1004)-4),{1,2,3})),""))&IF(Calc!D7>3,CHAR(10)&"+"&(Calc!D7-3)&" more",""))} -> 0 | E11: {=IF($A11="","",_xlfn.TEXTJOIN(CHAR(10),TRUE,IFERROR(INDEX('Activity Planner'!$B$5:$B$1004,SMALL(IF(('Activity Planner'!$C$5:$C$1004=$A11)*('Activity Planner'!$R$5:$R$1004=1),ROW('Activity Planner'!$B$5:$B$1004)-4),{1,2,3})),""))&IF(Calc!E7>3,CHAR(10)&"+"&(Calc!E7-3)&" more",""))} -> 0 | F11: {=IF($A11="","",_xlfn.TEXTJOIN(CHAR(10),TRUE,IFERROR(INDEX('Activity Planner'!$B$5:$B$1004,SMALL(IF(('Activity Planner'!$C$5:$C$1004=$A11)*('Activity Planner'!$S$5:$S$1004=1),ROW('Activity Planner'!$B$5:$B$1004)-4),{1,2,3})),""))&IF(Calc!F7>3,CHAR(10)&"+"&(Calc!F7-3)&" more",""))} -> 0 | G11: {=IF($A11="","",_xlfn.TEXTJOIN(CHAR(10),TRUE,IFERROR(INDEX('Activity Planner'!$B$5:$B$1004,SMALL(IF(('Activity Planner'!$C$5:$C$1004=$A11)*('Activity Planner'!$T$5:$T$1004=1),ROW('Activity Planner'!$B$5:$B$1004)-4),{1,2,3})),""))&IF(Calc!G7>3,CHAR(10)&"+"&(Calc!G7-3)&" more",""))} -> 0 | H11: {=IF($A11="","",_xlfn.TEXTJOIN(CHAR(10),TRUE,IFERROR(INDEX('Activity Planner'!$B$5:$B$1004,SMALL(IF(('Activity Planner'!$C$5:$C$1004=$A11)*('Activity Planner'!$U$5:$U$1004=1),ROW('Activity Planner'!$B$5:$B$1004)-4),{1,2,3})),""))&IF(Calc!H7>3,CHAR(10)&"+"&(Calc!H7-3)&" more",""))} -> 0 | I11: {=IF($A11="","",_xlfn.TEXTJOIN(CHAR(10),TRUE,IFERROR(INDEX('Activity Planner'!$B$5:$B$1004,SMALL(IF(('Activity Planner'!$C$5:$C$1004=$A11)*('Activity Planner'!$V$5:$V$1004=1),ROW('Activity Planner'!$B$5:$B$1004)-4),{1,2,3})),""))&IF(Calc!I7>3,CHAR(10)&"+"&(Calc!I7-3)&" more",""))} -> 0 | J11: {=IF($A11="","",_xlfn.TEXTJOIN(CHAR(10),TRUE,IFERROR(INDEX('Activity Planner'!$B$5:$B$1004,SMALL(IF(('Activity Planner'!$C$5:$C$1004=$A11)*('Activity Planner'!$W$5:$W$1004=1),ROW('Activity Planner'!$B$5:$B$1004)-4),{1,2,3})),""))&IF(Calc!J7>3,CHAR(10)&"+"&(Calc!J7-3)&" more",""))} -> 0 | K11: {=IF($A11="","",_xlfn.TEXTJOIN(CHAR(10),TRUE,IFERROR(INDEX('Activity Planner'!$B$5:$B$1004,SMALL(IF(('Activity Planner'!$C$5:$C$1004=$A11)*('Activity Planner'!$X$5:$X$1004=1),ROW('Activity Planner'!$B$5:$B$1004)-4),{1,2,3})),""))&IF(Calc!K7>3,CHAR(10)&"+"&(Calc!K7-3)&" more",""))} -> 0 | L11: {=IF($A11="","",_xlfn.TEXTJOIN(CHAR(10),TRUE,IFERROR(INDEX('Activity Planner'!$B$5:$B$1004,SMALL(IF(('Activity Planner'!$C$5:$C$1004=$A11)*('Activity Planner'!$Y$5:$Y$1004=1),ROW('Activity Planner'!$B$5:$B$1004)-4),{1,2,3})),""))&IF(Calc!L7>3,CHAR(10)&"+"&(Calc!L7-3)&" more",""))} -> 0 | M11: {=IF($A11="","",_xlfn.TEXTJOIN(CHAR(10),TRUE,IFERROR(INDEX('Activity Planner'!$B$5:$B$1004,SMALL(IF(('Activity Planner'!$C$5:$C$1004=$A11)*('Activity Planner'!$Z$5:$Z$1004=1),ROW('Activity Planner'!$B$5:$B$1004)-4),{1,2,3})),""))&IF(Calc!M7>3,CHAR(10)&"+"&(Calc!M7-3)&" more",""))} -> 0
A12: =IF(Lists!$B$10="","",Lists!$B$10) -> 0 | B12: {=IF($A12="","",_xlfn.TEXTJOIN(CHAR(10),TRUE,IFERROR(INDEX('Activity Planner'!$B$5:$B$1004,SMALL(IF(('Activity Planner'!$C$5:$C$1004=$A12)*('Activity Planner'!$O$5:$O$1004=1),ROW('Activity Planner'!$B$5:$B$1004)-4),{1,2,3})),""))&IF(Calc!B8>3,CHAR(10)&"+"&(Calc!B8-3)&" more",""))} -> 0 | C12: {=IF($A12="","",_xlfn.TEXTJOIN(CHAR(10),TRUE,IFERROR(INDEX('Activity Planner'!$B$5:$B$1004,SMALL(IF(('Activity Planner'!$C$5:$C$1004=$A12)*('Activity Planner'!$P$5:$P$1004=1),ROW('Activity Planner'!$B$5:$B$1004)-4),{1,2,3})),""))&IF(Calc!C8>3,CHAR(10)&"+"&(Calc!C8-3)&" more",""))} -> 0 | D12: {=IF($A12="","",_xlfn.TEXTJOIN(CHAR(10),TRUE,IFERROR(INDEX('Activity Planner'!$B$5:$B$1004,SMALL(IF(('Activity Planner'!$C$5:$C$1004=$A12)*('Activity Planner'!$Q$5:$Q$1004=1),ROW('Activity Planner'!$B$5:$B$1004)-4),{1,2,3})),""))&IF(Calc!D8>3,CHAR(10)&"+"&(Calc!D8-3)&" more",""))} -> 0 | E12: {=IF($A12="","",_xlfn.TEXTJOIN(CHAR(10),TRUE,IFERROR(INDEX('Activity Planner'!$B$5:$B$1004,SMALL(IF(('Activity Planner'!$C$5:$C$1004=$A12)*('Activity Planner'!$R$5:$R$1004=1),ROW('Activity Planner'!$B$5:$B$1004)-4),{1,2,3})),""))&IF(Calc!E8>3,CHAR(10)&"+"&(Calc!E8-3)&" more",""))} -> 0 | F12: {=IF($A12="","",_xlfn.TEXTJOIN(CHAR(10),TRUE,IFERROR(INDEX('Activity Planner'!$B$5:$B$1004,SMALL(IF(('Activity Planner'!$C$5:$C$1004=$A12)*('Activity Planner'!$S$5:$S$1004=1),ROW('Activity Planner'!$B$5:$B$1004)-4),{1,2,3})),""))&IF(Calc!F8>3,CHAR(10)&"+"&(Calc!F8-3)&" more",""))} -> 0 | G12: {=IF($A12="","",_xlfn.TEXTJOIN(CHAR(10),TRUE,IFERROR(INDEX('Activity Planner'!$B$5:$B$1004,SMALL(IF(('Activity Planner'!$C$5:$C$1004=$A12)*('Activity Planner'!$T$5:$T$1004=1),ROW('Activity Planner'!$B$5:$B$1004)-4),{1,2,3})),""))&IF(Calc!G8>3,CHAR(10)&"+"&(Calc!G8-3)&" more",""))} -> 0 | H12: {=IF($A12="","",_xlfn.TEXTJOIN(CHAR(10),TRUE,IFERROR(INDEX('Activity Planner'!$B$5:$B$1004,SMALL(IF(('Activity Planner'!$C$5:$C$1004=$A12)*('Activity Planner'!$U$5:$U$1004=1),ROW('Activity Planner'!$B$5:$B$1004)-4),{1,2,3})),""))&IF(Calc!H8>3,CHAR(10)&"+"&(Calc!H8-3)&" more",""))} -> 0 | I12: {=IF($A12="","",_xlfn.TEXTJOIN(CHAR(10),TRUE,IFERROR(INDEX('Activity Planner'!$B$5:$B$1004,SMALL(IF(('Activity Planner'!$C$5:$C$1004=$A12)*('Activity Planner'!$V$5:$V$1004=1),ROW('Activity Planner'!$B$5:$B$1004)-4),{1,2,3})),""))&IF(Calc!I8>3,CHAR(10)&"+"&(Calc!I8-3)&" more",""))} -> 0 | J12: {=IF($A12="","",_xlfn.TEXTJOIN(CHAR(10),TRUE,IFERROR(INDEX('Activity Planner'!$B$5:$B$1004,SMALL(IF(('Activity Planner'!$C$5:$C$1004=$A12)*('Activity Planner'!$W$5:$W$1004=1),ROW('Activity Planner'!$B$5:$B$1004)-4),{1,2,3})),""))&IF(Calc!J8>3,CHAR(10)&"+"&(Calc!J8-3)&" more",""))} -> 0 | K12: {=IF($A12="","",_xlfn.TEXTJOIN(CHAR(10),TRUE,IFERROR(INDEX('Activity Planner'!$B$5:$B$1004,SMALL(IF(('Activity Planner'!$C$5:$C$1004=$A12)*('Activity Planner'!$X$5:$X$1004=1),ROW('Activity Planner'!$B$5:$B$1004)-4),{1,2,3})),""))&IF(Calc!K8>3,CHAR(10)&"+"&(Calc!K8-3)&" more",""))} -> 0 | L12: {=IF($A12="","",_xlfn.TEXTJOIN(CHAR(10),TRUE,IFERROR(INDEX('Activity Planner'!$B$5:$B$1004,SMALL(IF(('Activity Planner'!$C$5:$C$1004=$A12)*('Activity Planner'!$Y$5:$Y$1004=1),ROW('Activity Planner'!$B$5:$B$1004)-4),{1,2,3})),""))&IF(Calc!L8>3,CHAR(10)&"+"&(Calc!L8-3)&" more",""))} -> 0 | M12: {=IF($A12="","",_xlfn.TEXTJOIN(CHAR(10),TRUE,IFERROR(INDEX('Activity Planner'!$B$5:$B$1004,SMALL(IF(('Activity Planner'!$C$5:$C$1004=$A12)*('Activity Planner'!$Z$5:$Z$1004=1),ROW('Activity Planner'!$B$5:$B$1004)-4),{1,2,3})),""))&IF(Calc!M8>3,CHAR(10)&"+"&(Calc!M8-3)&" more",""))} -> 0
A13: =IF(Lists!$B$11="","",Lists!$B$11) -> 0 | B13: {=IF($A13="","",_xlfn.TEXTJOIN(CHAR(10),TRUE,IFERROR(INDEX('Activity Planner'!$B$5:$B$1004,SMALL(IF(('Activity Planner'!$C$5:$C$1004=$A13)*('Activity Planner'!$O$5:$O$1004=1),ROW('Activity Planner'!$B$5:$B$1004)-4),{1,2,3})),""))&IF(Calc!B9>3,CHAR(10)&"+"&(Calc!B9-3)&" more",""))} -> 0 | C13: {=IF($A13="","",_xlfn.TEXTJOIN(CHAR(10),TRUE,IFERROR(INDEX('Activity Planner'!$B$5:$B$1004,SMALL(IF(('Activity Planner'!$C$5:$C$1004=$A13)*('Activity Planner'!$P$5:$P$1004=1),ROW('Activity Planner'!$B$5:$B$1004)-4),{1,2,3})),""))&IF(Calc!C9>3,CHAR(10)&"+"&(Calc!C9-3)&" more",""))} -> 0 | D13: {=IF($A13="","",_xlfn.TEXTJOIN(CHAR(10),TRUE,IFERROR(INDEX('Activity Planner'!$B$5:$B$1004,SMALL(IF(('Activity Planner'!$C$5:$C$1004=$A13)*('Activity Planner'!$Q$5:$Q$1004=1),ROW('Activity Planner'!$B$5:$B$1004)-4),{1,2,3})),""))&IF(Calc!D9>3,CHAR(10)&"+"&(Calc!D9-3)&" more",""))} -> 0 | E13: {=IF($A13="","",_xlfn.TEXTJOIN(CHAR(10),TRUE,IFERROR(INDEX('Activity Planner'!$B$5:$B$1004,SMALL(IF(('Activity Planner'!$C$5:$C$1004=$A13)*('Activity Planner'!$R$5:$R$1004=1),ROW('Activity Planner'!$B$5:$B$1004)-4),{1,2,3})),""))&IF(Calc!E9>3,CHAR(10)&"+"&(Calc!E9-3)&" more",""))} -> 0 | F13: {=IF($A13="","",_xlfn.TEXTJOIN(CHAR(10),TRUE,IFERROR(INDEX('Activity Planner'!$B$5:$B$1004,SMALL(IF(('Activity Planner'!$C$5:$C$1004=$A13)*('Activity Planner'!$S$5:$S$1004=1),ROW('Activity Planner'!$B$5:$B$1004)-4),{1,2,3})),""))&IF(Calc!F9>3,CHAR(10)&"+"&(Calc!F9-3)&" more",""))} -> 0 | G13: {=IF($A13="","",_xlfn.TEXTJOIN(CHAR(10),TRUE,IFERROR(INDEX('Activity Planner'!$B$5:$B$1004,SMALL(IF(('Activity Planner'!$C$5:$C$1004=$A13)*('Activity Planner'!$T$5:$T$1004=1),ROW('Activity Planner'!$B$5:$B$1004)-4),{1,2,3})),""))&IF(Calc!G9>3,CHAR(10)&"+"&(Calc!G9-3)&" more",""))} -> 0 | H13: {=IF($A13="","",_xlfn.TEXTJOIN(CHAR(10),TRUE,IFERROR(INDEX('Activity Planner'!$B$5:$B$1004,SMALL(IF(('Activity Planner'!$C$5:$C$1004=$A13)*('Activity Planner'!$U$5:$U$1004=1),ROW('Activity Planner'!$B$5:$B$1004)-4),{1,2,3})),""))&IF(Calc!H9>3,CHAR(10)&"+"&(Calc!H9-3)&" more",""))} -> 0 | I13: {=IF($A13="","",_xlfn.TEXTJOIN(CHAR(10),TRUE,IFERROR(INDEX('Activity Planner'!$B$5:$B$1004,SMALL(IF(('Activity Planner'!$C$5:$C$1004=$A13)*('Activity Planner'!$V$5:$V$1004=1),ROW('Activity Planner'!$B$5:$B$1004)-4),{1,2,3})),""))&IF(Calc!I9>3,CHAR(10)&"+"&(Calc!I9-3)&" more",""))} -> 0 | J13: {=IF($A13="","",_xlfn.TEXTJOIN(CHAR(10),TRUE,IFERROR(INDEX('Activity Planner'!$B$5:$B$1004,SMALL(IF(('Activity Planner'!$C$5:$C$1004=$A13)*('Activity Planner'!$W$5:$W$1004=1),ROW('Activity Planner'!$B$5:$B$1004)-4),{1,2,3})),""))&IF(Calc!J9>3,CHAR(10)&"+"&(Calc!J9-3)&" more",""))} -> 0 | K13: {=IF($A13="","",_xlfn.TEXTJOIN(CHAR(10),TRUE,IFERROR(INDEX('Activity Planner'!$B$5:$B$1004,SMALL(IF(('Activity Planner'!$C$5:$C$1004=$A13)*('Activity Planner'!$X$5:$X$1004=1),ROW('Activity Planner'!$B$5:$B$1004)-4),{1,2,3})),""))&IF(Calc!K9>3,CHAR(10)&"+"&(Calc!K9-3)&" more",""))} -> 0 | L13: {=IF($A13="","",_xlfn.TEXTJOIN(CHAR(10),TRUE,IFERROR(INDEX('Activity Planner'!$B$5:$B$1004,SMALL(IF(('Activity Planner'!$C$5:$C$1004=$A13)*('Activity Planner'!$Y$5:$Y$1004=1),ROW('Activity Planner'!$B$5:$B$1004)-4),{1,2,3})),""))&IF(Calc!L9>3,CHAR(10)&"+"&(Calc!L9-3)&" more",""))} -> 0 | M13: {=IF($A13="","",_xlfn.TEXTJOIN(CHAR(10),TRUE,IFERROR(INDEX('Activity Planner'!$B$5:$B$1004,SMALL(IF(('Activity Planner'!$C$5:$C$1004=$A13)*('Activity Planner'!$Z$5:$Z$1004=1),ROW('Activity Planner'!$B$5:$B$1004)-4),{1,2,3})),""))&IF(Calc!M9>3,CHAR(10)&"+"&(Calc!M9-3)&" more",""))} -> 0
A14: =IF(Lists!$B$12="","",Lists!$B$12) -> 0 | B14: {=IF($A14="","",_xlfn.TEXTJOIN(CHAR(10),TRUE,IFERROR(INDEX('Activity Planner'!$B$5:$B$1004,SMALL(IF(('Activity Planner'!$C$5:$C$1004=$A14)*('Activity Planner'!$O$5:$O$1004=1),ROW('Activity Planner'!$B$5:$B$1004)-4),{1,2,3})),""))&IF(Calc!B10>3,CHAR(10)&"+"&(Calc!B10-3)&" more",""))} -> 0 | C14: {=IF($A14="","",_xlfn.TEXTJOIN(CHAR(10),TRUE,IFERROR(INDEX('Activity Planner'!$B$5:$B$1004,SMALL(IF(('Activity Planner'!$C$5:$C$1004=$A14)*('Activity Planner'!$P$5:$P$1004=1),ROW('Activity Planner'!$B$5:$B$1004)-4),{1,2,3})),""))&IF(Calc!C10>3,CHAR(10)&"+"&(Calc!C10-3)&" more",""))} -> 0 | D14: {=IF($A14="","",_xlfn.TEXTJOIN(CHAR(10),TRUE,IFERROR(INDEX('Activity Planner'!$B$5:$B$1004,SMALL(IF(('Activity Planner'!$C$5:$C$1004=$A14)*('Activity Planner'!$Q$5:$Q$1004=1),ROW('Activity Planner'!$B$5:$B$1004)-4),{1,2,3})),""))&IF(Calc!D10>3,CHAR(10)&"+"&(Calc!D10-3)&" more",""))} -> 0 | E14: {=IF($A14="","",_xlfn.TEXTJOIN(CHAR(10),TRUE,IFERROR(INDEX('Activity Planner'!$B$5:$B$1004,SMALL(IF(('Activity Planner'!$C$5:$C$1004=$A14)*('Activity Planner'!$R$5:$R$1004=1),ROW('Activity Planner'!$B$5:$B$1004)-4),{1,2,3})),""))&IF(Calc!E10>3,CHAR(10)&"+"&(Calc!E10-3)&" more",""))} -> 0 | F14: {=IF($A14="","",_xlfn.TEXTJOIN(CHAR(10),TRUE,IFERROR(INDEX('Activity Planner'!$B$5:$B$1004,SMALL(IF(('Activity Planner'!$C$5:$C$1004=$A14)*('Activity Planner'!$S$5:$S$1004=1),ROW('Activity Planner'!$B$5:$B$1004)-4),{1,2,3})),""))&IF(Calc!F10>3,CHAR(10)&"+"&(Calc!F10-3)&" more",""))} -> 0 | G14: {=IF($A14="","",_xlfn.TEXTJOIN(CHAR(10),TRUE,IFERROR(INDEX('Activity Planner'!$B$5:$B$1004,SMALL(IF(('Activity Planner'!$C$5:$C$1004=$A14)*('Activity Planner'!$T$5:$T$1004=1),ROW('Activity Planner'!$B$5:$B$1004)-4),{1,2,3})),""))&IF(Calc!G10>3,CHAR(10)&"+"&(Calc!G10-3)&" more",""))} -> 0 | H14: {=IF($A14="","",_xlfn.TEXTJOIN(CHAR(10),TRUE,IFERROR(INDEX('Activity Planner'!$B$5:$B$1004,SMALL(IF(('Activity Planner'!$C$5:$C$1004=$A14)*('Activity Planner'!$U$5:$U$1004=1),ROW('Activity Planner'!$B$5:$B$1004)-4),{1,2,3})),""))&IF(Calc!H10>3,CHAR(10)&"+"&(Calc!H10-3)&" more",""))} -> 0 | I14: {=IF($A14="","",_xlfn.TEXTJOIN(CHAR(10),TRUE,IFERROR(INDEX('Activity Planner'!$B$5:$B$1004,SMALL(IF(('Activity Planner'!$C$5:$C$1004=$A14)*('Activity Planner'!$V$5:$V$1004=1),ROW('Activity Planner'!$B$5:$B$1004)-4),{1,2,3})),""))&IF(Calc!I10>3,CHAR(10)&"+"&(Calc!I10-3)&" more",""))} -> 0 | J14: {=IF($A14="","",_xlfn.TEXTJOIN(CHAR(10),TRUE,IFERROR(INDEX('Activity Planner'!$B$5:$B$1004,SMALL(IF(('Activity Planner'!$C$5:$C$1004=$A14)*('Activity Planner'!$W$5:$W$1004=1),ROW('Activity Planner'!$B$5:$B$1004)-4),{1,2,3})),""))&IF(Calc!J10>3,CHAR(10)&"+"&(Calc!J10-3)&" more",""))} -> 0 | K14: {=IF($A14="","",_xlfn.TEXTJOIN(CHAR(10),TRUE,IFERROR(INDEX('Activity Planner'!$B$5:$B$1004,SMALL(IF(('Activity Planner'!$C$5:$C$1004=$A14)*('Activity Planner'!$X$5:$X$1004=1),ROW('Activity Planner'!$B$5:$B$1004)-4),{1,2,3})),""))&IF(Calc!K10>3,CHAR(10)&"+"&(Calc!K10-3)&" more",""))} -> 0 | L14: {=IF($A14="","",_xlfn.TEXTJOIN(CHAR(10),TRUE,IFERROR(INDEX('Activity Planner'!$B$5:$B$1004,SMALL(IF(('Activity Planner'!$C$5:$C$1004=$A14)*('Activity Planner'!$Y$5:$Y$1004=1),ROW('Activity Planner'!$B$5:$B$1004)-4),{1,2,3})),""))&IF(Calc!L10>3,CHAR(10)&"+"&(Calc!L10-3)&" more",""))} -> 0 | M14: {=IF($A14="","",_xlfn.TEXTJOIN(CHAR(10),TRUE,IFERROR(INDEX('Activity Planner'!$B$5:$B$1004,SMALL(IF(('Activity Planner'!$C$5:$C$1004=$A14)*('Activity Planner'!$Z$5:$Z$1004=1),ROW('Activity Planner'!$B$5:$B$1004)-4),{1,2,3})),""))&IF(Calc!M10>3,CHAR(10)&"+"&(Calc!M10-3)&" more",""))} -> 0
A15: =IF(Lists!$B$13="","",Lists!$B$13) -> 0 | B15: {=IF($A15="","",_xlfn.TEXTJOIN(CHAR(10),TRUE,IFERROR(INDEX('Activity Planner'!$B$5:$B$1004,SMALL(IF(('Activity Planner'!$C$5:$C$1004=$A15)*('Activity Planner'!$O$5:$O$1004=1),ROW('Activity Planner'!$B$5:$B$1004)-4),{1,2,3})),""))&IF(Calc!B11>3,CHAR(10)&"+"&(Calc!B11-3)&" more",""))} -> 0 | C15: {=IF($A15="","",_xlfn.TEXTJOIN(CHAR(10),TRUE,IFERROR(INDEX('Activity Planner'!$B$5:$B$1004,SMALL(IF(('Activity Planner'!$C$5:$C$1004=$A15)*('Activity Planner'!$P$5:$P$1004=1),ROW('Activity Planner'!$B$5:$B$1004)-4),{1,2,3})),""))&IF(Calc!C11>3,CHAR(10)&"+"&(Calc!C11-3)&" more",""))} -> 0 | D15: {=IF($A15="","",_xlfn.TEXTJOIN(CHAR(10),TRUE,IFERROR(INDEX('Activity Planner'!$B$5:$B$1004,SMALL(IF(('Activity Planner'!$C$5:$C$1004=$A15)*('Activity Planner'!$Q$5:$Q$1004=1),ROW('Activity Planner'!$B$5:$B$1004)-4),{1,2,3})),""))&IF(Calc!D11>3,CHAR(10)&"+"&(Calc!D11-3)&" more",""))} -> 0 | E15: {=IF($A15="","",_xlfn.TEXTJOIN(CHAR(10),TRUE,IFERROR(INDEX('Activity Planner'!$B$5:$B$1004,SMALL(IF(('Activity Planner'!$C$5:$C$1004=$A15)*('Activity Planner'!$R$5:$R$1004=1),ROW('Activity Planner'!$B$5:$B$1004)-4),{1,2,3})),""))&IF(Calc!E11>3,CHAR(10)&"+"&(Calc!E11-3)&" more",""))} -> 0 | F15: {=IF($A15="","",_xlfn.TEXTJOIN(CHAR(10),TRUE,IFERROR(INDEX('Activity Planner'!$B$5:$B$1004,SMALL(IF(('Activity Planner'!$C$5:$C$1004=$A15)*('Activity Planner'!$S$5:$S$1004=1),ROW('Activity Planner'!$B$5:$B$1004)-4),{1,2,3})),""))&IF(Calc!F11>3,CHAR(10)&"+"&(Calc!F11-3)&" more",""))} -> 0 | G15: {=IF($A15="","",_xlfn.TEXTJOIN(CHAR(10),TRUE,IFERROR(INDEX('Activity Planner'!$B$5:$B$1004,SMALL(IF(('Activity Planner'!$C$5:$C$1004=$A15)*('Activity Planner'!$T$5:$T$1004=1),ROW('Activity Planner'!$B$5:$B$1004)-4),{1,2,3})),""))&IF(Calc!G11>3,CHAR(10)&"+"&(Calc!G11-3)&" more",""))} -> 0 | H15: {=IF($A15="","",_xlfn.TEXTJOIN(CHAR(10),TRUE,IFERROR(INDEX('Activity Planner'!$B$5:$B$1004,SMALL(IF(('Activity Planner'!$C$5:$C$1004=$A15)*('Activity Planner'!$U$5:$U$1004=1),ROW('Activity Planner'!$B$5:$B$1004)-4),{1,2,3})),""))&IF(Calc!H11>3,CHAR(10)&"+"&(Calc!H11-3)&" more",""))} -> 0 | I15: {=IF($A15="","",_xlfn.TEXTJOIN(CHAR(10),TRUE,IFERROR(INDEX('Activity Planner'!$B$5:$B$1004,SMALL(IF(('Activity Planner'!$C$5:$C$1004=$A15)*('Activity Planner'!$V$5:$V$1004=1),ROW('Activity Planner'!$B$5:$B$1004)-4),{1,2,3})),""))&IF(Calc!I11>3,CHAR(10)&"+"&(Calc!I11-3)&" more",""))} -> 0 | J15: {=IF($A15="","",_xlfn.TEXTJOIN(CHAR(10),TRUE,IFERROR(INDEX('Activity Planner'!$B$5:$B$1004,SMALL(IF(('Activity Planner'!$C$5:$C$1004=$A15)*('Activity Planner'!$W$5:$W$1004=1),ROW('Activity Planner'!$B$5:$B$1004)-4),{1,2,3})),""))&IF(Calc!J11>3,CHAR(10)&"+"&(Calc!J11-3)&" more",""))} -> 0 | K15: {=IF($A15="","",_xlfn.TEXTJOIN(CHAR(10),TRUE,IFERROR(INDEX('Activity Planner'!$B$5:$B$1004,SMALL(IF(('Activity Planner'!$C$5:$C$1004=$A15)*('Activity Planner'!$X$5:$X$1004=1),ROW('Activity Planner'!$B$5:$B$1004)-4),{1,2,3})),""))&IF(Calc!K11>3,CHAR(10)&"+"&(Calc!K11-3)&" more",""))} -> 0 | L15: {=IF($A15="","",_xlfn.TEXTJOIN(CHAR(10),TRUE,IFERROR(INDEX('Activity Planner'!$B$5:$B$1004,SMALL(IF(('Activity Planner'!$C$5:$C$1004=$A15)*('Activity Planner'!$Y$5:$Y$1004=1),ROW('Activity Planner'!$B$5:$B$1004)-4),{1,2,3})),""))&IF(Calc!L11>3,CHAR(10)&"+"&(Calc!L11-3)&" more",""))} -> 0 | M15: {=IF($A15="","",_xlfn.TEXTJOIN(CHAR(10),TRUE,IFERROR(INDEX('Activity Planner'!$B$5:$B$1004,SMALL(IF(('Activity Planner'!$C$5:$C$1004=$A15)*('Activity Planner'!$Z$5:$Z$1004=1),ROW('Activity Planner'!$B$5:$B$1004)-4),{1,2,3})),""))&IF(Calc!M11>3,CHAR(10)&"+"&(Calc!M11-3)&" more",""))} -> 0
A16: =IF(Lists!$B$14="","",Lists!$B$14) -> 0 | B16: {=IF($A16="","",_xlfn.TEXTJOIN(CHAR(10),TRUE,IFERROR(INDEX('Activity Planner'!$B$5:$B$1004,SMALL(IF(('Activity Planner'!$C$5:$C$1004=$A16)*('Activity Planner'!$O$5:$O$1004=1),ROW('Activity Planner'!$B$5:$B$1004)-4),{1,2,3})),""))&IF(Calc!B12>3,CHAR(10)&"+"&(Calc!B12-3)&" more",""))} -> 0 | C16: {=IF($A16="","",_xlfn.TEXTJOIN(CHAR(10),TRUE,IFERROR(INDEX('Activity Planner'!$B$5:$B$1004,SMALL(IF(('Activity Planner'!$C$5:$C$1004=$A16)*('Activity Planner'!$P$5:$P$1004=1),ROW('Activity Planner'!$B$5:$B$1004)-4),{1,2,3})),""))&IF(Calc!C12>3,CHAR(10)&"+"&(Calc!C12-3)&" more",""))} -> 0 | D16: {=IF($A16="","",_xlfn.TEXTJOIN(CHAR(10),TRUE,IFERROR(INDEX('Activity Planner'!$B$5:$B$1004,SMALL(IF(('Activity Planner'!$C$5:$C$1004=$A16)*('Activity Planner'!$Q$5:$Q$1004=1),ROW('Activity Planner'!$B$5:$B$1004)-4),{1,2,3})),""))&IF(Calc!D12>3,CHAR(10)&"+"&(Calc!D12-3)&" more",""))} -> 0 | E16: {=IF($A16="","",_xlfn.TEXTJOIN(CHAR(10),TRUE,IFERROR(INDEX('Activity Planner'!$B$5:$B$1004,SMALL(IF(('Activity Planner'!$C$5:$C$1004=$A16)*('Activity Planner'!$R$5:$R$1004=1),ROW('Activity Planner'!$B$5:$B$1004)-4),{1,2,3})),""))&IF(Calc!E12>3,CHAR(10)&"+"&(Calc!E12-3)&" more",""))} -> 0 | F16: {=IF($A16="","",_xlfn.TEXTJOIN(CHAR(10),TRUE,IFERROR(INDEX('Activity Planner'!$B$5:$B$1004,SMALL(IF(('Activity Planner'!$C$5:$C$1004=$A16)*('Activity Planner'!$S$5:$S$1004=1),ROW('Activity Planner'!$B$5:$B$1004)-4),{1,2,3})),""))&IF(Calc!F12>3,CHAR(10)&"+"&(Calc!F12-3)&" more",""))} -> 0 | G16: {=IF($A16="","",_xlfn.TEXTJOIN(CHAR(10),TRUE,IFERROR(INDEX('Activity Planner'!$B$5:$B$1004,SMALL(IF(('Activity Planner'!$C$5:$C$1004=$A16)*('Activity Planner'!$T$5:$T$1004=1),ROW('Activity Planner'!$B$5:$B$1004)-4),{1,2,3})),""))&IF(Calc!G12>3,CHAR(10)&"+"&(Calc!G12-3)&" more",""))} -> 0 | H16: {=IF($A16="","",_xlfn.TEXTJOIN(CHAR(10),TRUE,IFERROR(INDEX('Activity Planner'!$B$5:$B$1004,SMALL(IF(('Activity Planner'!$C$5:$C$1004=$A16)*('Activity Planner'!$U$5:$U$1004=1),ROW('Activity Planner'!$B$5:$B$1004)-4),{1,2,3})),""))&IF(Calc!H12>3,CHAR(10)&"+"&(Calc!H12-3)&" more",""))} -> 0 | I16: {=IF($A16="","",_xlfn.TEXTJOIN(CHAR(10),TRUE,IFERROR(INDEX('Activity Planner'!$B$5:$B$1004,SMALL(IF(('Activity Planner'!$C$5:$C$1004=$A16)*('Activity Planner'!$V$5:$V$1004=1),ROW('Activity Planner'!$B$5:$B$1004)-4),{1,2,3})),""))&IF(Calc!I12>3,CHAR(10)&"+"&(Calc!I12-3)&" more",""))} -> 0 | J16: {=IF($A16="","",_xlfn.TEXTJOIN(CHAR(10),TRUE,IFERROR(INDEX('Activity Planner'!$B$5:$B$1004,SMALL(IF(('Activity Planner'!$C$5:$C$1004=$A16)*('Activity Planner'!$W$5:$W$1004=1),ROW('Activity Planner'!$B$5:$B$1004)-4),{1,2,3})),""))&IF(Calc!J12>3,CHAR(10)&"+"&(Calc!J12-3)&" more",""))} -> 0 | K16: {=IF($A16="","",_xlfn.TEXTJOIN(CHAR(10),TRUE,IFERROR(INDEX('Activity Planner'!$B$5:$B$1004,SMALL(IF(('Activity Planner'!$C$5:$C$1004=$A16)*('Activity Planner'!$X$5:$X$1004=1),ROW('Activity Planner'!$B$5:$B$1004)-4),{1,2,3})),""))&IF(Calc!K12>3,CHAR(10)&"+"&(Calc!K12-3)&" more",""))} -> 0 | L16: {=IF($A16="","",_xlfn.TEXTJOIN(CHAR(10),TRUE,IFERROR(INDEX('Activity Planner'!$B$5:$B$1004,SMALL(IF(('Activity Planner'!$C$5:$C$1004=$A16)*('Activity Planner'!$Y$5:$Y$1004=1),ROW('Activity Planner'!$B$5:$B$1004)-4),{1,2,3})),""))&IF(Calc!L12>3,CHAR(10)&"+"&(Calc!L12-3)&" more",""))} -> 0 | M16: {=IF($A16="","",_xlfn.TEXTJOIN(CHAR(10),TRUE,IFERROR(INDEX('Activity Planner'!$B$5:$B$1004,SMALL(IF(('Activity Planner'!$C$5:$C$1004=$A16)*('Activity Planner'!$Z$5:$Z$1004=1),ROW('Activity Planner'!$B$5:$B$1004)-4),{1,2,3})),""))&IF(Calc!M12>3,CHAR(10)&"+"&(Calc!M12-3)&" more",""))} -> 0
A17: =IF(Lists!$B$15="","",Lists!$B$15) -> 0 | B17: {=IF($A17="","",_xlfn.TEXTJOIN(CHAR(10),TRUE,IFERROR(INDEX('Activity Planner'!$B$5:$B$1004,SMALL(IF(('Activity Planner'!$C$5:$C$1004=$A17)*('Activity Planner'!$O$5:$O$1004=1),ROW('Activity Planner'!$B$5:$B$1004)-4),{1,2,3})),""))&IF(Calc!B13>3,CHAR(10)&"+"&(Calc!B13-3)&" more",""))} -> 0 | C17: {=IF($A17="","",_xlfn.TEXTJOIN(CHAR(10),TRUE,IFERROR(INDEX('Activity Planner'!$B$5:$B$1004,SMALL(IF(('Activity Planner'!$C$5:$C$1004=$A17)*('Activity Planner'!$P$5:$P$1004=1),ROW('Activity Planner'!$B$5:$B$1004)-4),{1,2,3})),""))&IF(Calc!C13>3,CHAR(10)&"+"&(Calc!C13-3)&" more",""))} -> 0 | D17: {=IF($A17="","",_xlfn.TEXTJOIN(CHAR(10),TRUE,IFERROR(INDEX('Activity Planner'!$B$5:$B$1004,SMALL(IF(('Activity Planner'!$C$5:$C$1004=$A17)*('Activity Planner'!$Q$5:$Q$1004=1),ROW('Activity Planner'!$B$5:$B$1004)-4),{1,2,3})),""))&IF(Calc!D13>3,CHAR(10)&"+"&(Calc!D13-3)&" more",""))} -> 0 | E17: {=IF($A17="","",_xlfn.TEXTJOIN(CHAR(10),TRUE,IFERROR(INDEX('Activity Planner'!$B$5:$B$1004,SMALL(IF(('Activity Planner'!$C$5:$C$1004=$A17)*('Activity Planner'!$R$5:$R$1004=1),ROW('Activity Planner'!$B$5:$B$1004)-4),{1,2,3})),""))&IF(Calc!E13>3,CHAR(10)&"+"&(Calc!E13-3)&" more",""))} -> 0 | F17: {=IF($A17="","",_xlfn.TEXTJOIN(CHAR(10),TRUE,IFERROR(INDEX('Activity Planner'!$B$5:$B$1004,SMALL(IF(('Activity Planner'!$C$5:$C$1004=$A17)*('Activity Planner'!$S$5:$S$1004=1),ROW('Activity Planner'!$B$5:$B$1004)-4),{1,2,3})),""))&IF(Calc!F13>3,CHAR(10)&"+"&(Calc!F13-3)&" more",""))} -> 0 | G17: {=IF($A17="","",_xlfn.TEXTJOIN(CHAR(10),TRUE,IFERROR(INDEX('Activity Planner'!$B$5:$B$1004,SMALL(IF(('Activity Planner'!$C$5:$C$1004=$A17)*('Activity Planner'!$T$5:$T$1004=1),ROW('Activity Planner'!$B$5:$B$1004)-4),{1,2,3})),""))&IF(Calc!G13>3,CHAR(10)&"+"&(Calc!G13-3)&" more",""))} -> 0 | H17: {=IF($A17="","",_xlfn.TEXTJOIN(CHAR(10),TRUE,IFERROR(INDEX('Activity Planner'!$B$5:$B$1004,SMALL(IF(('Activity Planner'!$C$5:$C$1004=$A17)*('Activity Planner'!$U$5:$U$1004=1),ROW('Activity Planner'!$B$5:$B$1004)-4),{1,2,3})),""))&IF(Calc!H13>3,CHAR(10)&"+"&(Calc!H13-3)&" more",""))} -> 0 | I17: {=IF($A17="","",_xlfn.TEXTJOIN(CHAR(10),TRUE,IFERROR(INDEX('Activity Planner'!$B$5:$B$1004,SMALL(IF(('Activity Planner'!$C$5:$C$1004=$A17)*('Activity Planner'!$V$5:$V$1004=1),ROW('Activity Planner'!$B$5:$B$1004)-4),{1,2,3})),""))&IF(Calc!I13>3,CHAR(10)&"+"&(Calc!I13-3)&" more",""))} -> 0 | J17: {=IF($A17="","",_xlfn.TEXTJOIN(CHAR(10),TRUE,IFERROR(INDEX('Activity Planner'!$B$5:$B$1004,SMALL(IF(('Activity Planner'!$C$5:$C$1004=$A17)*('Activity Planner'!$W$5:$W$1004=1),ROW('Activity Planner'!$B$5:$B$1004)-4),{1,2,3})),""))&IF(Calc!J13>3,CHAR(10)&"+"&(Calc!J13-3)&" more",""))} -> 0 | K17: {=IF($A17="","",_xlfn.TEXTJOIN(CHAR(10),TRUE,IFERROR(INDEX('Activity Planner'!$B$5:$B$1004,SMALL(IF(('Activity Planner'!$C$5:$C$1004=$A17)*('Activity Planner'!$X$5:$X$1004=1),ROW('Activity Planner'!$B$5:$B$1004)-4),{1,2,3})),""))&IF(Calc!K13>3,CHAR(10)&"+"&(Calc!K13-3)&" more",""))} -> 0 | L17: {=IF($A17="","",_xlfn.TEXTJOIN(CHAR(10),TRUE,IFERROR(INDEX('Activity Planner'!$B$5:$B$1004,SMALL(IF(('Activity Planner'!$C$5:$C$1004=$A17)*('Activity Planner'!$Y$5:$Y$1004=1),ROW('Activity Planner'!$B$5:$B$1004)-4),{1,2,3})),""))&IF(Calc!L13>3,CHAR(10)&"+"&(Calc!L13-3)&" more",""))} -> 0 | M17: {=IF($A17="","",_xlfn.TEXTJOIN(CHAR(10),TRUE,IFERROR(INDEX('Activity Planner'!$B$5:$B$1004,SMALL(IF(('Activity Planner'!$C$5:$C$1004=$A17)*('Activity Planner'!$Z$5:$Z$1004=1),ROW('Activity Planner'!$B$5:$B$1004)-4),{1,2,3})),""))&IF(Calc!M13>3,CHAR(10)&"+"&(Calc!M13-3)&" more",""))} -> 0
A18: =IF(Lists!$B$16="","",Lists!$B$16) -> 0 | B18: {=IF($A18="","",_xlfn.TEXTJOIN(CHAR(10),TRUE,IFERROR(INDEX('Activity Planner'!$B$5:$B$1004,SMALL(IF(('Activity Planner'!$C$5:$C$1004=$A18)*('Activity Planner'!$O$5:$O$1004=1),ROW('Activity Planner'!$B$5:$B$1004)-4),{1,2,3})),""))&IF(Calc!B14>3,CHAR(10)&"+"&(Calc!B14-3)&" more",""))} -> 0 | C18: {=IF($A18="","",_xlfn.TEXTJOIN(CHAR(10),TRUE,IFERROR(INDEX('Activity Planner'!$B$5:$B$1004,SMALL(IF(('Activity Planner'!$C$5:$C$1004=$A18)*('Activity Planner'!$P$5:$P$1004=1),ROW('Activity Planner'!$B$5:$B$1004)-4),{1,2,3})),""))&IF(Calc!C14>3,CHAR(10)&"+"&(Calc!C14-3)&" more",""))} -> 0 | D18: {=IF($A18="","",_xlfn.TEXTJOIN(CHAR(10),TRUE,IFERROR(INDEX('Activity Planner'!$B$5:$B$1004,SMALL(IF(('Activity Planner'!$C$5:$C$1004=$A18)*('Activity Planner'!$Q$5:$Q$1004=1),ROW('Activity Planner'!$B$5:$B$1004)-4),{1,2,3})),""))&IF(Calc!D14>3,CHAR(10)&"+"&(Calc!D14-3)&" more",""))} -> 0 | E18: {=IF($A18="","",_xlfn.TEXTJOIN(CHAR(10),TRUE,IFERROR(INDEX('Activity Planner'!$B$5:$B$1004,SMALL(IF(('Activity Planner'!$C$5:$C$1004=$A18)*('Activity Planner'!$R$5:$R$1004=1),ROW('Activity Planner'!$B$5:$B$1004)-4),{1,2,3})),""))&IF(Calc!E14>3,CHAR(10)&"+"&(Calc!E14-3)&" more",""))} -> 0 | F18: {=IF($A18="","",_xlfn.TEXTJOIN(CHAR(10),TRUE,IFERROR(INDEX('Activity Planner'!$B$5:$B$1004,SMALL(IF(('Activity Planner'!$C$5:$C$1004=$A18)*('Activity Planner'!$S$5:$S$1004=1),ROW('Activity Planner'!$B$5:$B$1004)-4),{1,2,3})),""))&IF(Calc!F14>3,CHAR(10)&"+"&(Calc!F14-3)&" more",""))} -> 0 | G18: {=IF($A18="","",_xlfn.TEXTJOIN(CHAR(10),TRUE,IFERROR(INDEX('Activity Planner'!$B$5:$B$1004,SMALL(IF(('Activity Planner'!$C$5:$C$1004=$A18)*('Activity Planner'!$T$5:$T$1004=1),ROW('Activity Planner'!$B$5:$B$1004)-4),{1,2,3})),""))&IF(Calc!G14>3,CHAR(10)&"+"&(Calc!G14-3)&" more",""))} -> 0 | H18: {=IF($A18="","",_xlfn.TEXTJOIN(CHAR(10),TRUE,IFERROR(INDEX('Activity Planner'!$B$5:$B$1004,SMALL(IF(('Activity Planner'!$C$5:$C$1004=$A18)*('Activity Planner'!$U$5:$U$1004=1),ROW('Activity Planner'!$B$5:$B$1004)-4),{1,2,3})),""))&IF(Calc!H14>3,CHAR(10)&"+"&(Calc!H14-3)&" more",""))} -> 0 | I18: {=IF($A18="","",_xlfn.TEXTJOIN(CHAR(10),TRUE,IFERROR(INDEX('Activity Planner'!$B$5:$B$1004,SMALL(IF(('Activity Planner'!$C$5:$C$1004=$A18)*('Activity Planner'!$V$5:$V$1004=1),ROW('Activity Planner'!$B$5:$B$1004)-4),{1,2,3})),""))&IF(Calc!I14>3,CHAR(10)&"+"&(Calc!I14-3)&" more",""))} -> 0 | J18: {=IF($A18="","",_xlfn.TEXTJOIN(CHAR(10),TRUE,IFERROR(INDEX('Activity Planner'!$B$5:$B$1004,SMALL(IF(('Activity Planner'!$C$5:$C$1004=$A18)*('Activity Planner'!$W$5:$W$1004=1),ROW('Activity Planner'!$B$5:$B$1004)-4),{1,2,3})),""))&IF(Calc!J14>3,CHAR(10)&"+"&(Calc!J14-3)&" more",""))} -> 0 | K18: {=IF($A18="","",_xlfn.TEXTJOIN(CHAR(10),TRUE,IFERROR(INDEX('Activity Planner'!$B$5:$B$1004,SMALL(IF(('Activity Planner'!$C$5:$C$1004=$A18)*('Activity Planner'!$X$5:$X$1004=1),ROW('Activity Planner'!$B$5:$B$1004)-4),{1,2,3})),""))&IF(Calc!K14>3,CHAR(10)&"+"&(Calc!K14-3)&" more",""))} -> 0 | L18: {=IF($A18="","",_xlfn.TEXTJOIN(CHAR(10),TRUE,IFERROR(INDEX('Activity Planner'!$B$5:$B$1004,SMALL(IF(('Activity Planner'!$C$5:$C$1004=$A18)*('Activity Planner'!$Y$5:$Y$1004=1),ROW('Activity Planner'!$B$5:$B$1004)-4),{1,2,3})),""))&IF(Calc!L14>3,CHAR(10)&"+"&(Calc!L14-3)&" more",""))} -> 0 | M18: {=IF($A18="","",_xlfn.TEXTJOIN(CHAR(10),TRUE,IFERROR(INDEX('Activity Planner'!$B$5:$B$1004,SMALL(IF(('Activity Planner'!$C$5:$C$1004=$A18)*('Activity Planner'!$Z$5:$Z$1004=1),ROW('Activity Planner'!$B$5:$B$1004)-4),{1,2,3})),""))&IF(Calc!M14>3,CHAR(10)&"+"&(Calc!M14-3)&" more",""))} -> 0
A20: LEGEND | B20: Create the reason to care | D20: Build momentum | F20: Create opportunity
A22: WHY THIS VIEW | B22: 01 CONNECT | F22: 02 COMPOUND | J22: 03 COORDINATE
B23: See where one market moment or activity can support multiple priorities. | F23: Build on existing momentum rather than creating isolated activity from scratch. | J23: Identify collisions, gaps and opportunities for better sequencing across the portfolio.
A26: ACTIVITIES BY MONTH (an activity counts in every month it touches; Year column counts each activity once)
B27: JAN | C27: FEB | D27: MAR | E27: APR | F27: MAY | G27: JUN | H27: JUL | I27: AUG | J27: SEP | K27: OCT | L27: NOV | M27: DEC | N27: YEAR
A28: Total activities | B28: =SUM(Calc!B3:B14) -> 0 | C28: =SUM(Calc!C3:C14) -> 0 | D28: =SUM(Calc!D3:D14) -> 0 | E28: =SUM(Calc!E3:E14) -> 0 | F28: =SUM(Calc!F3:F14) -> 0 | G28: =SUM(Calc!G3:G14) -> 0 | H28: =SUM(Calc!H3:H14) -> 0 | I28: =SUM(Calc!I3:I14) -> 0 | ... M28: =SUM(Calc!M3:M14) -> 0 | N28: =COUNTIFS('Activity Planner'!$AA$5:$AA$1004,">0") -> 0
A29: of which Events | B29: =SUM(Calc!B63:B74) -> 0 | C29: =SUM(Calc!C63:C74) -> 0 | D29: =SUM(Calc!D63:D74) -> 0 | E29: =SUM(Calc!E63:E74) -> 0 | F29: =SUM(Calc!F63:F74) -> 0 | G29: =SUM(Calc!G63:G74) -> 0 | H29: =SUM(Calc!H63:H74) -> 0 | I29: =SUM(Calc!I63:I74) -> 0 | ... M29: =SUM(Calc!M63:M74) -> 0 | N29: =COUNTIFS('Activity Planner'!$AA$5:$AA$1004,">0",'Activity Planner'!$E$5:$E$1004,"Event") -> 0
A30: Other activities | B30: =B28-B29 -> 0 | C30: =C28-C29 -> 0 | D30: =D28-D29 -> 0 | E30: =E28-E29 -> 0 | F30: =F28-F29 -> 0 | G30: =G28-G29 -> 0 | H30: =H28-H29 -> 0 | I30: =I28-I29 -> 0 | ... N30: =N28-N29 -> 0
A31: Create the reason to care | B31: =SUM(Calc!B18:B29) -> 0 | C31: =SUM(Calc!C18:C29) -> 0 | D31: =SUM(Calc!D18:D29) -> 0 | E31: =SUM(Calc!E18:E29) -> 0 | F31: =SUM(Calc!F18:F29) -> 0 | G31: =SUM(Calc!G18:G29) -> 0 | H31: =SUM(Calc!H18:H29) -> 0 | I31: =SUM(Calc!I18:I29) -> 0 | ... M31: =SUM(Calc!M18:M29) -> 0 | N31: =COUNTIFS('Activity Planner'!$AA$5:$AA$1004,">0",'Activity Planner'!$D$5:$D$1004,Lists!$E$5) -> 0
A32: Build momentum | B32: =SUM(Calc!B33:B44) -> 0 | C32: =SUM(Calc!C33:C44) -> 0 | D32: =SUM(Calc!D33:D44) -> 0 | E32: =SUM(Calc!E33:E44) -> 0 | F32: =SUM(Calc!F33:F44) -> 0 | G32: =SUM(Calc!G33:G44) -> 0 | H32: =SUM(Calc!H33:H44) -> 0 | I32: =SUM(Calc!I33:I44) -> 0 | ... M32: =SUM(Calc!M33:M44) -> 0 | N32: =COUNTIFS('Activity Planner'!$AA$5:$AA$1004,">0",'Activity Planner'!$D$5:$D$1004,Lists!$E$6) -> 0
A33: Create opportunity | B33: =SUM(Calc!B48:B59) -> 0 | C33: =SUM(Calc!C48:C59) -> 0 | D33: =SUM(Calc!D48:D59) -> 0 | E33: =SUM(Calc!E48:E59) -> 0 | F33: =SUM(Calc!F48:F59) -> 0 | G33: =SUM(Calc!G48:G59) -> 0 | H33: =SUM(Calc!H48:H59) -> 0 | I33: =SUM(Calc!I48:I59) -> 0 | ... M33: =SUM(Calc!M48:M59) -> 0 | N33: =COUNTIFS('Activity Planner'!$AA$5:$AA$1004,">0",'Activity Planner'!$D$5:$D$1004,Lists!$E$7) -> 0
A36: BY PRACTICE AND MOTION (whole year, each activity counted once)
A37: PRACTICE | B37: CREATE THE REASON TO CARE | C37: BUILD MOMENTUM | D37: CREATE OPPORTUNITY | E37: TOTAL | F37: EVENTS
A38: =$A7 -> 0 | B38: =IF($A38="","",COUNTIFS('Activity Planner'!$C$5:$C$1004,$A38,'Activity Planner'!$D$5:$D$1004,Lists!$E$5,'Activity Planner'!$AA$5:$AA$1004,">0")) -> 0 | C38: =IF($A38="","",COUNTIFS('Activity Planner'!$C$5:$C$1004,$A38,'Activity Planner'!$D$5:$D$1004,Lists!$E$6,'Activity Planner'!$AA$5:$AA$1004,">0")) -> 0 | D38: =IF($A38="","",COUNTIFS('Activity Planner'!$C$5:$C$1004,$A38,'Activity Planner'!$D$5:$D$1004,Lists!$E$7,'Activity Planner'!$AA$5:$AA$1004,">0")) -> 0 | E38: =IF($A38="","",COUNTIFS('Activity Planner'!$C$5:$C$1004,$A38,'Activity Planner'!$AA$5:$AA$1004,">0")) -> 0 | F38: =IF($A38="","",COUNTIFS('Activity Planner'!$C$5:$C$1004,$A38,'Activity Planner'!$E$5:$E$1004,"Event",'Activity Planner'!$AA$5:$AA$1004,">0")) -> 0
A39: =$A8 -> 0 | B39: =IF($A39="","",COUNTIFS('Activity Planner'!$C$5:$C$1004,$A39,'Activity Planner'!$D$5:$D$1004,Lists!$E$5,'Activity Planner'!$AA$5:$AA$1004,">0")) -> 0 | C39: =IF($A39="","",COUNTIFS('Activity Planner'!$C$5:$C$1004,$A39,'Activity Planner'!$D$5:$D$1004,Lists!$E$6,'Activity Planner'!$AA$5:$AA$1004,">0")) -> 0 | D39: =IF($A39="","",COUNTIFS('Activity Planner'!$C$5:$C$1004,$A39,'Activity Planner'!$D$5:$D$1004,Lists!$E$7,'Activity Planner'!$AA$5:$AA$1004,">0")) -> 0 | E39: =IF($A39="","",COUNTIFS('Activity Planner'!$C$5:$C$1004,$A39,'Activity Planner'!$AA$5:$AA$1004,">0")) -> 0 | F39: =IF($A39="","",COUNTIFS('Activity Planner'!$C$5:$C$1004,$A39,'Activity Planner'!$E$5:$E$1004,"Event",'Activity Planner'!$AA$5:$AA$1004,">0")) -> 0
A40: =$A9 -> 0 | B40: =IF($A40="","",COUNTIFS('Activity Planner'!$C$5:$C$1004,$A40,'Activity Planner'!$D$5:$D$1004,Lists!$E$5,'Activity Planner'!$AA$5:$AA$1004,">0")) -> 0 | C40: =IF($A40="","",COUNTIFS('Activity Planner'!$C$5:$C$1004,$A40,'Activity Planner'!$D$5:$D$1004,Lists!$E$6,'Activity Planner'!$AA$5:$AA$1004,">0")) -> 0 | D40: =IF($A40="","",COUNTIFS('Activity Planner'!$C$5:$C$1004,$A40,'Activity Planner'!$D$5:$D$1004,Lists!$E$7,'Activity Planner'!$AA$5:$AA$1004,">0")) -> 0 | E40: =IF($A40="","",COUNTIFS('Activity Planner'!$C$5:$C$1004,$A40,'Activity Planner'!$AA$5:$AA$1004,">0")) -> 0 | F40: =IF($A40="","",COUNTIFS('Activity Planner'!$C$5:$C$1004,$A40,'Activity Planner'!$E$5:$E$1004,"Event",'Activity Planner'!$AA$5:$AA$1004,">0")) -> 0
A41: =$A10 -> 0 | B41: =IF($A41="","",COUNTIFS('Activity Planner'!$C$5:$C$1004,$A41,'Activity Planner'!$D$5:$D$1004,Lists!$E$5,'Activity Planner'!$AA$5:$AA$1004,">0")) -> 0 | C41: =IF($A41="","",COUNTIFS('Activity Planner'!$C$5:$C$1004,$A41,'Activity Planner'!$D$5:$D$1004,Lists!$E$6,'Activity Planner'!$AA$5:$AA$1004,">0")) -> 0 | D41: =IF($A41="","",COUNTIFS('Activity Planner'!$C$5:$C$1004,$A41,'Activity Planner'!$D$5:$D$1004,Lists!$E$7,'Activity Planner'!$AA$5:$AA$1004,">0")) -> 0 | E41: =IF($A41="","",COUNTIFS('Activity Planner'!$C$5:$C$1004,$A41,'Activity Planner'!$AA$5:$AA$1004,">0")) -> 0 | F41: =IF($A41="","",COUNTIFS('Activity Planner'!$C$5:$C$1004,$A41,'Activity Planner'!$E$5:$E$1004,"Event",'Activity Planner'!$AA$5:$AA$1004,">0")) -> 0
A42: =$A11 -> 0 | B42: =IF($A42="","",COUNTIFS('Activity Planner'!$C$5:$C$1004,$A42,'Activity Planner'!$D$5:$D$1004,Lists!$E$5,'Activity Planner'!$AA$5:$AA$1004,">0")) -> 0 | C42: =IF($A42="","",COUNTIFS('Activity Planner'!$C$5:$C$1004,$A42,'Activity Planner'!$D$5:$D$1004,Lists!$E$6,'Activity Planner'!$AA$5:$AA$1004,">0")) -> 0 | D42: =IF($A42="","",COUNTIFS('Activity Planner'!$C$5:$C$1004,$A42,'Activity Planner'!$D$5:$D$1004,Lists!$E$7,'Activity Planner'!$AA$5:$AA$1004,">0")) -> 0 | E42: =IF($A42="","",COUNTIFS('Activity Planner'!$C$5:$C$1004,$A42,'Activity Planner'!$AA$5:$AA$1004,">0")) -> 0 | F42: =IF($A42="","",COUNTIFS('Activity Planner'!$C$5:$C$1004,$A42,'Activity Planner'!$E$5:$E$1004,"Event",'Activity Planner'!$AA$5:$AA$1004,">0")) -> 0
A43: =$A12 -> 0 | B43: =IF($A43="","",COUNTIFS('Activity Planner'!$C$5:$C$1004,$A43,'Activity Planner'!$D$5:$D$1004,Lists!$E$5,'Activity Planner'!$AA$5:$AA$1004,">0")) -> 0 | C43: =IF($A43="","",COUNTIFS('Activity Planner'!$C$5:$C$1004,$A43,'Activity Planner'!$D$5:$D$1004,Lists!$E$6,'Activity Planner'!$AA$5:$AA$1004,">0")) -> 0 | D43: =IF($A43="","",COUNTIFS('Activity Planner'!$C$5:$C$1004,$A43,'Activity Planner'!$D$5:$D$1004,Lists!$E$7,'Activity Planner'!$AA$5:$AA$1004,">0")) -> 0 | E43: =IF($A43="","",COUNTIFS('Activity Planner'!$C$5:$C$1004,$A43,'Activity Planner'!$AA$5:$AA$1004,">0")) -> 0 | F43: =IF($A43="","",COUNTIFS('Activity Planner'!$C$5:$C$1004,$A43,'Activity Planner'!$E$5:$E$1004,"Event",'Activity Planner'!$AA$5:$AA$1004,">0")) -> 0
A44: =$A13 -> 0 | B44: =IF($A44="","",COUNTIFS('Activity Planner'!$C$5:$C$1004,$A44,'Activity Planner'!$D$5:$D$1004,Lists!$E$5,'Activity Planner'!$AA$5:$AA$1004,">0")) -> 0 | C44: =IF($A44="","",COUNTIFS('Activity Planner'!$C$5:$C$1004,$A44,'Activity Planner'!$D$5:$D$1004,Lists!$E$6,'Activity Planner'!$AA$5:$AA$1004,">0")) -> 0 | D44: =IF($A44="","",COUNTIFS('Activity Planner'!$C$5:$C$1004,$A44,'Activity Planner'!$D$5:$D$1004,Lists!$E$7,'Activity Planner'!$AA$5:$AA$1004,">0")) -> 0 | E44: =IF($A44="","",COUNTIFS('Activity Planner'!$C$5:$C$1004,$A44,'Activity Planner'!$AA$5:$AA$1004,">0")) -> 0 | F44: =IF($A44="","",COUNTIFS('Activity Planner'!$C$5:$C$1004,$A44,'Activity Planner'!$E$5:$E$1004,"Event",'Activity Planner'!$AA$5:$AA$1004,">0")) -> 0
A45: =$A14 -> 0 | B45: =IF($A45="","",COUNTIFS('Activity Planner'!$C$5:$C$1004,$A45,'Activity Planner'!$D$5:$D$1004,Lists!$E$5,'Activity Planner'!$AA$5:$AA$1004,">0")) -> 0 | C45: =IF($A45="","",COUNTIFS('Activity Planner'!$C$5:$C$1004,$A45,'Activity Planner'!$D$5:$D$1004,Lists!$E$6,'Activity Planner'!$AA$5:$AA$1004,">0")) -> 0 | D45: =IF($A45="","",COUNTIFS('Activity Planner'!$C$5:$C$1004,$A45,'Activity Planner'!$D$5:$D$1004,Lists!$E$7,'Activity Planner'!$AA$5:$AA$1004,">0")) -> 0 | E45: =IF($A45="","",COUNTIFS('Activity Planner'!$C$5:$C$1004,$A45,'Activity Planner'!$AA$5:$AA$1004,">0")) -> 0 | F45: =IF($A45="","",COUNTIFS('Activity Planner'!$C$5:$C$1004,$A45,'Activity Planner'!$E$5:$E$1004,"Event",'Activity Planner'!$AA$5:$AA$1004,">0")) -> 0
A46: =$A15 -> 0 | B46: =IF($A46="","",COUNTIFS('Activity Planner'!$C$5:$C$1004,$A46,'Activity Planner'!$D$5:$D$1004,Lists!$E$5,'Activity Planner'!$AA$5:$AA$1004,">0")) -> 0 | C46: =IF($A46="","",COUNTIFS('Activity Planner'!$C$5:$C$1004,$A46,'Activity Planner'!$D$5:$D$1004,Lists!$E$6,'Activity Planner'!$AA$5:$AA$1004,">0")) -> 0 | D46: =IF($A46="","",COUNTIFS('Activity Planner'!$C$5:$C$1004,$A46,'Activity Planner'!$D$5:$D$1004,Lists!$E$7,'Activity Planner'!$AA$5:$AA$1004,">0")) -> 0 | E46: =IF($A46="","",COUNTIFS('Activity Planner'!$C$5:$C$1004,$A46,'Activity Planner'!$AA$5:$AA$1004,">0")) -> 0 | F46: =IF($A46="","",COUNTIFS('Activity Planner'!$C$5:$C$1004,$A46,'Activity Planner'!$E$5:$E$1004,"Event",'Activity Planner'!$AA$5:$AA$1004,">0")) -> 0
A47: =$A16 -> 0 | B47: =IF($A47="","",COUNTIFS('Activity Planner'!$C$5:$C$1004,$A47,'Activity Planner'!$D$5:$D$1004,Lists!$E$5,'Activity Planner'!$AA$5:$AA$1004,">0")) -> 0 | C47: =IF($A47="","",COUNTIFS('Activity Planner'!$C$5:$C$1004,$A47,'Activity Planner'!$D$5:$D$1004,Lists!$E$6,'Activity Planner'!$AA$5:$AA$1004,">0")) -> 0 | D47: =IF($A47="","",COUNTIFS('Activity Planner'!$C$5:$C$1004,$A47,'Activity Planner'!$D$5:$D$1004,Lists!$E$7,'Activity Planner'!$AA$5:$AA$1004,">0")) -> 0 | E47: =IF($A47="","",COUNTIFS('Activity Planner'!$C$5:$C$1004,$A47,'Activity Planner'!$AA$5:$AA$1004,">0")) -> 0 | F47: =IF($A47="","",COUNTIFS('Activity Planner'!$C$5:$C$1004,$A47,'Activity Planner'!$E$5:$E$1004,"Event",'Activity Planner'!$AA$5:$AA$1004,">0")) -> 0
...

Sheet Monthly View
A1: MONTHLY VIEW | K1: =MATCH($B$5,MonthList,0) -> 0
A2: One month, in detail.
A3: Pick a month to see what is happening, for which practice, and in which motion.
A5: Select month: | B5: March | C5: ="Planning year "&PlanYear&" | Showing: "&StatusFilter -> 0
A7: TOTAL ACTIVITIES | B7: EVENTS | C7: CREATE THE REASON TO CARE | D7: BUILD MOMENTUM | E7: CREATE OPPORTUNITY
A8: =SUMPRODUCT(INDEX('Activity Planner'!$O$5:$Z$1004,0,SelMonthNum)) -> 0 | B8: =SUMPRODUCT(INDEX('Activity Planner'!$O$5:$Z$1004,0,SelMonthNum)*('Activity Planner'!$E$5:$E$1004="Event")) -> 0 | C8: =SUMPRODUCT(INDEX('Activity Planner'!$O$5:$Z$1004,0,SelMonthNum)*('Activity Planner'!$D$5:$D$1004=Lists!$E$5)) -> 0 | D8: =SUMPRODUCT(INDEX('Activity Planner'!$O$5:$Z$1004,0,SelMonthNum)*('Activity Planner'!$D$5:$D$1004=Lists!$E$6)) -> 0 | E8: =SUMPRODUCT(INDEX('Activity Planner'!$O$5:$Z$1004,0,SelMonthNum)*('Activity Planner'!$D$5:$D$1004=Lists!$E$7)) -> 0
A11: PRACTICE BY MOTION
A12: PRACTICE | B12: Create the reason to care | C12: Build momentum | D12: Create opportunity | E12: TOTAL
A13: =IF(Lists!$B$5="","",Lists!$B$5) -> 0 | B13: =IF($A13="","",SUMPRODUCT(INDEX('Activity Planner'!$O$5:$Z$1004,0,SelMonthNum)*('Activity Planner'!$C$5:$C$1004=$A13)*('Activity Planner'!$D$5:$D$1004=Lists!$E$5))) -> 0 | C13: =IF($A13="","",SUMPRODUCT(INDEX('Activity Planner'!$O$5:$Z$1004,0,SelMonthNum)*('Activity Planner'!$C$5:$C$1004=$A13)*('Activity Planner'!$D$5:$D$1004=Lists!$E$6))) -> 0 | D13: =IF($A13="","",SUMPRODUCT(INDEX('Activity Planner'!$O$5:$Z$1004,0,SelMonthNum)*('Activity Planner'!$C$5:$C$1004=$A13)*('Activity Planner'!$D$5:$D$1004=Lists!$E$7))) -> 0 | E13: =IF($A13="","",SUM(B13:D13)) -> 0
A14: =IF(Lists!$B$6="","",Lists!$B$6) -> 0 | B14: =IF($A14="","",SUMPRODUCT(INDEX('Activity Planner'!$O$5:$Z$1004,0,SelMonthNum)*('Activity Planner'!$C$5:$C$1004=$A14)*('Activity Planner'!$D$5:$D$1004=Lists!$E$5))) -> 0 | C14: =IF($A14="","",SUMPRODUCT(INDEX('Activity Planner'!$O$5:$Z$1004,0,SelMonthNum)*('Activity Planner'!$C$5:$C$1004=$A14)*('Activity Planner'!$D$5:$D$1004=Lists!$E$6))) -> 0 | D14: =IF($A14="","",SUMPRODUCT(INDEX('Activity Planner'!$O$5:$Z$1004,0,SelMonthNum)*('Activity Planner'!$C$5:$C$1004=$A14)*('Activity Planner'!$D$5:$D$1004=Lists!$E$7))) -> 0 | E14: =IF($A14="","",SUM(B14:D14)) -> 0
A15: =IF(Lists!$B$7="","",Lists!$B$7) -> 0 | B15: =IF($A15="","",SUMPRODUCT(INDEX('Activity Planner'!$O$5:$Z$1004,0,SelMonthNum)*('Activity Planner'!$C$5:$C$1004=$A15)*('Activity Planner'!$D$5:$D$1004=Lists!$E$5))) -> 0 | C15: =IF($A15="","",SUMPRODUCT(INDEX('Activity Planner'!$O$5:$Z$1004,0,SelMonthNum)*('Activity Planner'!$C$5:$C$1004=$A15)*('Activity Planner'!$D$5:$D$1004=Lists!$E$6))) -> 0 | D15: =IF($A15="","",SUMPRODUCT(INDEX('Activity Planner'!$O$5:$Z$1004,0,SelMonthNum)*('Activity Planner'!$C$5:$C$1004=$A15)*('Activity Planner'!$D$5:$D$1004=Lists!$E$7))) -> 0 | E15: =IF($A15="","",SUM(B15:D15)) -> 0
